Workbook

Sheet CENARIO ATUAL BOA E AVENIDA
A1: CLIENTE | B1: SERVIÇO | C1: QNTD CONTRATO | D1: LAVAÇAO NOT. | E1: QNTD TOTAL FAT | F1: VALOR UNIT. | G1: VALOR TOTAL
A2: IRMÃOS BOA - HORTOLANDIA (LOJA 01) | B2: LIMPEZA | C2: 5 | E2: =C2+D2 -> 5 | F2: 5654.7946 | G2: =F2*E2 -> 28273.973
A3: IRMÃOS BOA - ANHANGUERA (LOJA 02) | B3: LIMPEZA | C3: 2 | E3: =C3+D3 -> 2 | F3: 5660.4407 | G3: =F3*E3 -> 11320.881
A4: IRMÃOS BOA - IMIGRANTES (LOJA 03) | B4: LIMPEZA | C4: 6 | D4: 1 | E4: =C4+D4 -> 7 | F4: 5660.4421 | G4: =F4*E4 -> 39623.095
A5: IRMÃOS BOA - CABREÚVA (LOJA 05) | B5: LIMPEZA | C5: 5 | E5: =C5+D5 -> 5 | F5: 5660.4407 | G5: =F5*E5 -> 28302.204
A6: IRMÃOS BOA - CABREÚVA (LOJA 05) | B6: FISCAL | C6: 5 | E6: =C6+D6 -> 5 | F6: 6705.3528 | G6: =F6*E6 -> 33526.764
A7: IRMÃOS BOA - CENTENARIO (LOJA 06) | B7: LIMPEZA | C7: 6 | E7: =C7+D7 -> 6 | F7: 5654.7903 | G7: =F7*E7 -> 33928.742
A8: IRMÃOS BOA - DOM OLIVIO (LOJA 15) CD 07 | B8: LIMPEZA | C8: 2 | E8: =C8+D8 -> 2 | F8: 5660.4407 | G8: =F8*E8 -> 11320.881
A9: IRMÃOS BOA - VARZEA PAULISTA (LOJA 08) | B9: LIMPEZA | C9: 6 | D9: 1 | E9: =C9+D9 -> 7 | F9: 5654.7911 | G9: =F9*E9 -> 39583.538
A10: IRMÃOS BOA - VILA RAMI (LOJA 09) | B10: LIMPEZA | C10: 5 | E10: =C10+D10 -> 5 | F10: 5668.3284 | G10: =F10*E10 -> 28341.642
A11: IRMÃOS BOA - FRANCISCO MORATO (LOJA 10) | B11: LIMPEZA | C11: 6 | D11: 1 | E11: =C11+D11 -> 7 | F11: 5654.7911 | G11: =F11*E11 -> 39583.538
A12: IRMÃO BOA - LIBERDADE (LOJA 11) | B12: LIMPEZA | C12: 2 | E12: =C12+D12 -> 2 | F12: 5660.4407 | G12: =F12*E12 -> 11320.881
A13: IRMÃOS BOA - SOROCABA (LOJA 12) | B13: LIMPEZA | C13: 5 | E13: =C13+D13 -> 5 | F13: 5660.4407 | G13: =F13*E13 -> 28302.204
A14: IRMÃOS BOA - SOROCABA (LOJA 12) | B14: FISCAL | C14: 5 | E14: =C14+D14 -> 5 | F14: 6705.3528 | G14: =F14*E14 -> 33526.764
A15: IRMÃOS BOA - CENTRO (LOJA 13) | B15: LIMPEZA | C15: 5 | E15: =C15+D15 -> 5 | F15: 5654.7946 | G15: =F15*E15 -> 28273.973
A16: IRMÃOS BOA - VILA ARENS (LOJA 14) | B16: LIMPEZA | C16: 5 | E16: =C16+D16 -> 5 | F16: 5660.4407 | G16: =F16*E16 -> 28302.204
A17: IRMÃOS BOA - DOM OLIVIO (LOJA 15) | B17: LIMPEZA | C17: 7 | E17: =C17+D17 -> 7 | F17: 5660.442 | G17: =F17*E17 -> 39623.094
A18: IRMÃOS BOA - DOM OLIVIO (LOJA 15) | B18: SEGURANÇA | D18: 1 | E18: =C18+D18 -> 1 | F18: 3995.9244 | G18: =F18*E18 -> 3995.9244
A19: IRMÃOS BOA - CAMPO LIMPO (LOJA 16) | B19: LIMPEZA | C19: 6 | D19: 1 | E19: =C19+D19 -> 7 | F19: 5660.4421 | G19: =F19*E19 -> 39623.095
A20: IRMÃO BOA - ELOY CHAVES (LOJA17) | B20: LIMPEZA | C20: 5 | E20: =C20+D20 -> 5 | F20: 5660.44 | G20: =F20*E20 -> 28302.2
A21: IRMAOS BOA CD ITUPEVA (LOJA 18) | B21: LIMPEZA | C21: 2 | E21: =C21+D21 -> 2 | F21: 5660.44 | G21: =F21*E21 -> 11320.88
A22: IRMÃO BOA - 19 | B22: LIMPEZA | C22: 5 | E22: =C22+D22 -> 5 | F22: 5660.442 | G22: =F22*E22 -> 28302.21
A23: IRMÃOS BOA - CECAP (LOJA 21) | B23: LIMPEZA | C23: 5 | E23: =C23+D23 -> 5 | F23: 5660.4407 | G23: =F23*E23 -> 28302.204
A24: IRMÃO BOA - VALINHOS (LOJA 22) | B24: LIMPEZA | C24: 5 | E24: =C24+D24 -> 5 | F24: 5660.442 | G24: =F24*E24 -> 28302.21
A25: IRMÃO BOA - VALINHOS (LOJA 22) | B25: FISCAL | C25: 5 | E25: =C25+D25 -> 5 | F25: 6705.3528 | G25: =F25*E25 -> 33526.764
A26: IRMÃO BOA - PAULINIA (LOJA 23) | B26: LIMPEZA | C26: 5 | E26: =C26+D26 -> 5 | F26: 6249 | G26: =F26*E26 -> 31245
A27: IRMÃOS BOA - DOM OLIVIO (LOJA 24) | B27: LIMPEZA | C27: 7 | E27: 7 | F27: 5660.442 | G27: =F27*E27 -> 39623.094
A28: IRMÃOS BOA - DOM OLIVIO (LOJA 24) | B28: FISCAL | C28: 1 | E28: 1 | F28: 6759.3756 | G28: =F28*E28 -> 6759.3756
A29: IRMÃOS BOA - PEDREIRA (LOJA 27) | B29: LIMPEZA | C29: 3 | E29: 3 | F29: 7366.1933 | G29: =F29*E29 -> 22098.58
C30: =SUM(C2:C29) -> 126 | D30: =SUM(D2:D29) -> 5 | E30: =SUM(E2:E29) -> 131 | G30: =SUM(G2:G29) -> 764555.91
A32: Inicio - implantação | B32: Loja | C32: Atual ou Futura | D32: UF | E32: Cidade | F32: Atual Nº funcionario 2024 | G32: Preço por funcionário | H32: Total Atual 2025
A33: 45300 | B33: Loja 10 | C33: Em operação | D33: SP | E33: Paraguaçu Paulista | F33: 3 | G33: 4160 | H33: =G33*F33 -> 12480
A34: 45300 | B34: Loja 11 | C34: Em operação | D34: SP | E34: Cândido Mota | F34: 2 | G34: 4160 | H34: =G34*F34 -> 8320
A35: 45300 | B35: Loja 25 | C35: Em operação | D35: SP | E35: Ourinhos | F35: 2 | G35: 4160 | H35: =G35*F35 -> 8320
A36: 45300 | B36: Loja 26 | C36: Em operação | D36: SP | E36: Santa Cruz do Rio Pardo | F36: 2 | G36: 4160 | H36: =G36*F36 -> 8320
A37: 45300 | B37: Loja 29 | C37: Em operação | D37: SP | E37: Presidente Prudente | F37: 2 | G37: 4160 | H37: =G37*F37 -> 8320
A38: 45300 | B38: Loja 31 | C38: Em operação | D38: SP | E38: Presidente Epitácio | F38: 2 | G38: 4160 | H38: =G38*F38 -> 8320
A39: 45300 | B39: Loja 32 | C39: Em operação | D39: SP | E39: Pirapozinho | F39: 2 | G39: 4160 | H39: =G39*F39 -> 8320
A40: 45323 | B40: Loja 7 | C40: Em operação | D40: SP | E40: Maracaí | F40: 2 | G40: 4160 | H40: =G40*F40 -> 8320
A41: 45323 | B41: Loja 9 | C41: Em operação | D41: SP | E41: Cândido Mota | F41: 2 | G41: 4160 | H41: =G41*F41 -> 8320
...

Sheet REDUÇÃO
A1: CLIENTE | B1: SERVIÇO | C1: QNTD CONTRATO | D1: LAVAÇAO NOT. | E1: QNTD TOTAL FAT | F1: VALOR UNIT. | G1: VALOR TOTAL | H1: REDUÇÃO
A2: IRMÃOS BOA - CABREÚVA (LOJA 05) | B2: LIMPEZA | C2: 5 | E2: =C2+D2 -> 5 | F2: 5660.4407 | G2: =F2*C2 -> 28302.204 | H2: =F2*C2 -> 28302.204
A3: IRMÃOS BOA - CABREÚVA (LOJA 05) | B3: FISCAL | C3: 5 | E3: =C3+D3 -> 5 | F3: 6705.3528 | G3: =F3*E3 -> 33526.764 | H3: =F3*C3 -> 33526.764
A4: IRMÃOS BOA - VARZEA PAULISTA (LOJA 08) | B4: LIMPEZA | C4: 6 | D4: 1 | E4: =C4+D4 -> 7 | F4: 5654.7911 | G4: =F4*E4 -> 39583.538 | H4: =F4*C4 -> 33928.747
A5: IRMÃOS BOA - FRANCISCO MORATO (LOJA 10) | B5: LIMPEZA | C5: 6 | D5: 1 | E5: =C5+D5 -> 7 | F5: 5654.7911 | G5: =F5*E5 -> 39583.538 | H5: =F5*C5 -> 33928.747
A6: IRMÃOS BOA - SOROCABA (LOJA 12) | B6: LIMPEZA | C6: 5 | E6: =C6+D6 -> 5 | F6: 5660.4407 | G6: =F6*E6 -> 28302.204 | H6: =F6*C6 -> 28302.204
A7: IRMÃOS BOA - SOROCABA (LOJA 12) | B7: FISCAL | C7: 5 | E7: =C7+D7 -> 5 | F7: 6705.3528 | G7: =F7*E7 -> 33526.764 | H7: =F7*C7 -> 33526.764
A8: IRMÃOS BOA - CAMPO LIMPO (LOJA 16) | B8: LIMPEZA | C8: 6 | D8: 1 | E8: =C8+D8 -> 7 | F8: 5660.4421 | G8: =F8*E8 -> 39623.095 | H8: =F8*C8 -> 33962.653
A9: IRMÃO BOA - VALINHOS (LOJA 22) | B9: LIMPEZA | C9: 5 | E9: =C9+D9 -> 5 | F9: 5660.442 | G9: =F9*E9 -> 28302.21 | H9: =F9*C9 -> 28302.21
A10: IRMÃO BOA - VALINHOS (LOJA 22) | B10: FISCAL | C10: 5 | E10: =C10+D10 -> 5 | F10: 6705.3528 | G10: =F10*E10 -> 33526.764 | H10: =F10*C10 -> 33526.764
A11: IRMÃO BOA - PAULINIA (LOJA 23) | B11: LIMPEZA | C11: 5 | E11: =C11+D11 -> 5 | F11: 6249 | G11: =F11*E11 -> 31245 | H11: =F11*C11 -> 31245
A12: IRMÃOS BOA - DOM OLIVIO (LOJA 24) | B12: LIMPEZA | C12: 7 | E12: 7 | F12: 5660.442 | G12: =F12*E12 -> 39623.094 | H12: =F12*C12 -> 39623.094
A13: IRMÃOS BOA - DOM OLIVIO (LOJA 24) | B13: FISCAL | C13: 1 | E13: 1 | F13: 6759.3756 | G13: =F13*E13 -> 6759.3756 | H13: =F13*C13 -> 6759.3756
A14: IRMÃOS BOA - PEDREIRA (LOJA 27) | B14: LIMPEZA | C14: 3 | E14: 3 | F14: 7366.1933 | G14: =F14*3 -> 22098.58 | H14: =F14*C14 -> 22098.58
C15: =SUM(C2:C14) -> 64 | D15: =SUM(D2:D14) -> 3 | E15: =SUM(E2:E14) -> 67 | G15: =SUM(G2:G14) -> 404003.13 | H15: =SUM(H2:H14) -> 387033.1
A20: Inicio - implantação | B20: Loja | C20: Atual ou Futura | D20: UF | E20: Cidade | F20: Atual Nº funcionario 2024 | G20: Preço por funcionário | H20: Total Atual 2025
A21: 45300 | B21: Loja 25 | C21: Em operação | D21: SP | E21: OURINHOS | F21: 2 | G21: 4160 | H21: =G21*F21 -> 8320
A22: 45483 | B22: LOJA 02 | C22: Em operação | D22: SP | E22: ASSIS | F22: 2 | G22: 4160 | H22: =G22*F22 -> 8320
A23: 45483 | B23: LOJA 03 | C23: Em operação | D23: SP | E23: ASSIS | F23: 2 | G23: 4160 | H23: =G23*F23 -> 8320
A24: 45483 | B24: LOJA 04 | C24: Em operação | D24: SP | E24: ASSIS | F24: 3 | G24: 4160 | H24: =G24*F24 -> 12480
A25: 45483 | B25: LOJA 13 | C25: Em operação | D25: SP | E25: ASSIS | F25: 2 | G25: 4160 | H25: =G25*F25 -> 8320
A26: 45483 | B26: LOJA 20 | C26: Em operação | D26: SP | E26: ASSIS MAX | F26: 3 | G26: 4160 | H26: =G26*F26 -> 12480
A27: 45483 | B27: LOJA 14 | C27: Em operação | D27: SP | E27: OURINHOS | F27: 2 | G27: 4160 | H27: =G27*F27 -> 8320
A28: 45483 | B28: LOJA 27 | C28: Em operação | D28: SP | E28: OURINHOS | F28: 2 | G28: 4160 | H28: =G28*F28 -> 8320
A29: 45483 | B29: ESCRITORIO | C29: Em operação | D29: SP | E29: ASSIS | F29: 1 | G29: 4160 | H29: =G29*F29 -> 4160
F30: =SUM(F21:F29) -> 19 | H30: =SUM(H21:H29) -> 79040
B32: TOTAL COLAB. BOA E AVENIDA | C32: ='CENARIO ATUAL BOA E AVENIDA'!E30+'CENARIO ATUAL BOA E AVENIDA'!F72 -> 214 | E32: FAT. ATUAL BOA E AVENIDA | F32: ='CENARIO ATUAL BOA E AVENIDA'!F77 -> 1109835.9
B34: TOTAL COLAB. REDUZIDO | C34: =F30+C15 -> 83 | D34: =C34/C32 -> 0.38785047 | E34: TOTAL FAT. REDUZIDO | F34: =H15+H30 -> 466073.1 | G34: =F34/F32 -> 0.41994776
B36: PREVISAO COLAB. BOA E AVENIDA | C36: =C32-C34 -> 131 | D36: =C36/C32 -> 0.61214953 | E36: PREVISAO BOA E AVENIDA | F36: ='CENARIO ATUAL BOA E AVENIDA'!F77-REDUÇÃO!F34 -> 643762.81 | G36: =F36/F32 -> 0.58005224 | H36: PREVISAO BOA | I36: ='CENARIO ATUAL BOA E AVENIDA'!G30-REDUÇÃO!H15 -> 377522.81 | J36: =I36/F40 -> 0.34920807
E38: RECEITA GLOBAL ATUAL | F38: 1547155.8 | H38: PREVISAO AVENIDA | I38: ='CENARIO ATUAL BOA E AVENIDA'!H72-REDUÇÃO!H30 -> 266240 | J38: =I38/F40 -> 0.24627163
E40: RECEITA GLOBAL NOVA | F40: =F38-F34 -> 1081082.7 | G40: =F40/F38 -> 0.69875491

Sheet Planilha3
A1: CLIENTE | B1: CIDADE | C1: SERVIÇO | D1: QNTD CONTRATO | E1: VALOR UNITARIO | F1: REDUÇÃO
A2: IRMÃOS BOA - CABREÚVA (LOJA 05) | B2: CABREUVA | C2: LIMPEZA | D2: 5 | E2: 5660.4407 | F2: 28302.204
A3: IRMÃOS BOA - CABREÚVA (LOJA 05) | B3: CABREUVA | C3: FISCAL | D3: 5 | E3: 6705.3528 | F3: 33526.764
A4: IRMÃOS BOA - VARZEA PAULISTA (LOJA 08) | B4: VARZEA PAULISTA | C4: LIMPEZA | D4: 6 | E4: 5654.7911 | F4: 33928.747
A5: IRMÃOS BOA - FRANCISCO MORATO (LOJA 10) | B5: FRANCISCO MORATO | C5: LIMPEZA | D5: 6 | E5: 5654.7911 | F5: 33928.747
A6: IRMÃOS BOA - SOROCABA (LOJA 12) | B6: SOROCABA | C6: LIMPEZA | D6: 5 | E6: 5660.4407 | F6: 28302.204
A7: IRMÃOS BOA - SOROCABA (LOJA 12) | B7: SOROCABA | C7: FISCAL | D7: 5 | E7: 6705.3528 | F7: 33526.764
A8: IRMÃOS BOA - CAMPO LIMPO (LOJA 16) | B8: CAMPO LIMPO | C8: LIMPEZA | D8: 6 | E8: 5660.4421 | F8: 33962.653
A9: IRMÃO BOA - VALINHOS (LOJA 22) | B9: VALINHOS | C9: LIMPEZA | D9: 5 | E9: 5660.442 | F9: 28302.21
A10: IRMÃO BOA - VALINHOS (LOJA 22) | B10: VALINHOS | C10: FISCAL | D10: 5 | E10: 6705.3528 | F10: 33526.764
A11: IRMÃO BOA - PAULINIA (LOJA 23) | B11: PAULINIA | C11: LIMPEZA | D11: 5 | E11: 6249 | F11: 31245
A12: IRMÃOS BOA - DOM OLIVIO (LOJA 24) | B12: DOM OLIVIO | C12: LIMPEZA | D12: 7 | E12: 5660.442 | F12: 39623.094
A13: IRMÃOS BOA - DOM OLIVIO (LOJA 24) | B13: DOM OLIVIO | C13: FISCAL | D13: 1 | E13: 6759.3756 | F13: 6759.3756
... A23: ESCRITORIO | B23: ASSIS | C23: LIMPEZA | D23: 1 | E23: 4160 | F23: 4160
D24: =SUM(D2:D23) -> 83 | F24: =SUM(F2:F23) -> 466073.1

Sheet Planilha6
A1: CLIENTE | B1: SERVIÇO | C1: QNTD CONTRATO | D1: LAVAÇAO NOT. | E1: QNTD TOTAL FAT | F1: VALOR UNIT. | G1: VALOR TOTAL
A2: IRMÃOS BOA - HORTOLANDIA (LOJA 01) | B2: LIMPEZA | C2: 5 | E2: =C2+D2 -> 5 | F2: 5654.7946 | G2: =F2*E2 -> 28273.973
A3: IRMÃOS BOA - ANHANGUERA (LOJA 02) | B3: LIMPEZA | C3: 2 | E3: =C3+D3 -> 2 | F3: 5660.4407 | G3: =F3*E3 -> 11320.881
A4: IRMÃOS BOA - IMIGRANTES (LOJA 03) | B4: LIMPEZA | C4: 6 | D4: 1 | E4: =C4+D4 -> 7 | F4: 5660.4421 | G4: =F4*E4 -> 39623.095
A5: IRMÃOS BOA - CABREÚVA (LOJA 05) | B5: LIMPEZA | C5: 0 | E5: =C5+D5 -> 0 | F5: 5660.4407 | G5: =F5*E5 -> 0
A6: IRMÃOS BOA - CABREÚVA (LOJA 05) | B6: FISCAL | C6: 0 | E6: =C6+D6 -> 0 | F6: 6705.3528 | G6: =F6*E6 -> 0
A7: IRMÃOS BOA - CENTENARIO (LOJA 06) | B7: LIMPEZA | C7: 6 | E7: =C7+D7 -> 6 | F7: 5654.7903 | G7: =F7*E7 -> 33928.742
A8: IRMÃOS BOA - DOM OLIVIO (LOJA 15) CD 07 | B8: LIMPEZA | C8: 2 | E8: =C8+D8 -> 2 | F8: 5660.4407 | G8: =F8*E8 -> 11320.881
A9: IRMÃOS BOA - VARZEA PAULISTA (LOJA 08) | B9: LIMPEZA | C9: 0 | D9: 1 | E9: =C9+D9 -> 1 | F9: 5654.7911 | G9: =F9*E9 -> 5654.7911
A10: IRMÃOS BOA - VILA RAMI (LOJA 09) | B10: LIMPEZA | C10: 5 | E10: =C10+D10 -> 5 | F10: 5668.3284 | G10: =F10*E10 -> 28341.642
A11: IRMÃOS BOA - FRANCISCO MORATO (LOJA 10) | B11: LIMPEZA | C11: 0 | D11: 1 | E11: =C11+D11 -> 1 | F11: 5654.7911 | G11: =F11*E11 -> 5654.7911
A12: IRMÃO BOA - LIBERDADE (LOJA 11) | B12: LIMPEZA | C12: 2 | E12: =C12+D12 -> 2 | F12: 5660.4407 | G12: =F12*E12 -> 11320.881
A13: IRMÃOS BOA - SOROCABA (LOJA 12) | B13: LIMPEZA | C13: 0 | E13: =C13+D13 -> 0 | F13: 5660.4407 | G13: =F13*E13 -> 0
A14: IRMÃOS BOA - SOROCABA (LOJA 12) | B14: FISCAL | C14: 0 | E14: =C14+D14 -> 0 | F14: 6705.3528 | G14: =F14*E14 -> 0
A15: IRMÃOS BOA - CENTRO (LOJA 13) | B15: LIMPEZA | C15: 5 | E15: =C15+D15 -> 5 | F15: 5654.7946 | G15: =F15*E15 -> 28273.973
A16: IRMÃOS BOA - VILA ARENS (LOJA 14) | B16: LIMPEZA | C16: 5 | E16: =C16+D16 -> 5 | F16: 5660.4407 | G16: =F16*E16 -> 28302.204
A17: IRMÃOS BOA - DOM OLIVIO (LOJA 15) | B17: LIMPEZA | C17: 7 | E17: =C17+D17 -> 7 | F17: 5660.442 | G17: =F17*E17 -> 39623.094
A18: IRMÃOS BOA - DOM OLIVIO (LOJA 15) | B18: SEGURANÇA | D18: 1 | E18: =C18+D18 -> 1 | F18: 3995.9244 | G18: =F18*E18 -> 3995.9244
A19: IRMÃOS BOA - CAMPO LIMPO (LOJA 16) | B19: LIMPEZA | C19: 0 | D19: 1 | E19: =C19+D19 -> 1 | F19: 5660.4421 | G19: =F19*E19 -> 5660.4421
A20: IRMÃO BOA - ELOY CHAVES (LOJA17) | B20: LIMPEZA | C20: 5 | E20: =C20+D20 -> 5 | F20: 5660.44 | G20: =F20*E20 -> 28302.2
A21: IRMAOS BOA CD ITUPEVA (LOJA 18) | B21: LIMPEZA | C21: 2 | E21: =C21+D21 -> 2 | F21: 5660.44 | G21: =F21*E21 -> 11320.88
A22: IRMÃO BOA - 19 | B22: LIMPEZA | C22: 5 | E22: =C22+D22 -> 5 | F22: 5660.442 | G22: =F22*E22 -> 28302.21
A23: IRMÃOS BOA - CECAP (LOJA 21) | B23: LIMPEZA | C23: 5 | E23: =C23+D23 -> 5 | F23: 5660.4407 | G23: =F23*E23 -> 28302.204
A24: IRMÃO BOA - VALINHOS (LOJA 22) | B24: LIMPEZA | C24: 0 | E24: =C24+D24 -> 0 | F24: 5660.442 | G24: =F24*E24 -> 0
A25: IRMÃO BOA - VALINHOS (LOJA 22) | B25: FISCAL | C25: 0 | E25: =C25+D25 -> 0 | F25: 6705.3528 | G25: =F25*E25 -> 0
A26: IRMÃO BOA - PAULINIA (LOJA 23) | B26: LIMPEZA | C26: 0 | E26: =C26+D26 -> 0 | F26: 6249 | G26: =F26*E26 -> 0
A27: IRMÃOS BOA - DOM OLIVIO (LOJA 24) | B27: LIMPEZA | C27: 0 | E27: 0 | F27: 5660.442 | G27: =F27*E27 -> 0
A28: IRMÃOS BOA - DOM OLIVIO (LOJA 24) | B28: FISCAL | C28: 0 | E28: 0 | F28: 6759.3756 | G28: =F28*E28 -> 0
A29: IRMÃOS BOA - PEDREIRA (LOJA 27) | B29: LIMPEZA | C29: 0 | E29: 0 | F29: 7366.1933 | G29: =F29*E29 -> 0
G30: =SUM(G2:G29) -> 377522.81
G32: 266240
G34: =G30+G32 -> 643762.81
